Workbook

Sheet Base_IFData_Original
A1: BASE DE DADOS | IFData Junho 2026
A2: Fonte: IF.data, Banco Central do Brasil (https://www3.bcb.gov.br/ifdata)
A4: Instituição | B4: Código | C4: Conglomerado Prudencial (Nome) | D4: Conglomerado Financeiro (Cód.) | E4: Conglomerado Prudencial (Cód.) | F4: TCB | G4: TC | H4: TI | I4: Cidade | J4: UF | K4: Data | L4: Ativo Total (R$ mil) | M4: Carteira de Crédito (R$ mil) | N4: Títulos e Valores Mobiliários (R$ mil) | O4: Passivo Exigível (R$ mil) | P4: Captações (R$ mil) | Q4: Patrimônio Líquido (R$ mil) | R4: Lucro Líquido (R$ mil) | S4: Número de Agências | T4: Postos de Atendimento
A5: BANCO DO BRASIL S.A. | B5: 0 | C5: BB - PRUDENCIAL | D5: C0049906 | E5: C0080329 | F5: b1 | G5: 1 | H5: 1 | I5: BRASILIA | J5: DF | K5: 06/2026 | L5: 2461086914 | M5: 1065710905 | N5: 714731784 | O5: 2279753810 | P5: 1974660924 | Q5: 181333105 | R5: 6216056 | S5: 3932 | T5: 309
A6: CAIXA ECONOMICA FEDERAL | B6: 360305 | C6: CAIXA ECONÔMICA FEDERAL - PRUDENCIAL | D6: C0051626 | E6: C0080738 | F6: b1 | G6: 1 | H6: 6 | I6: BRASILIA | J6: DF | K6: 06/2026 | L6: 2368147225 | M6: 1362330927 | N6: 452416774 | O6: 2249779433 | P6: 2063880327 | Q6: 118367792 | R6: 6585794 | S6: 3000 | T6: 868
A7: ITAÚ UNIBANCO S.A. | B7: 60701190 | C7: ITAU - PRUDENCIAL | D7: C0010069 | E7: C0080099 | F7: b1 | G7: 2 | H7: 8 | I7: SAO PAULO | J7: SP | K7: 06/2026 | L7: 2169409565 | M7: 700105223 | N7: 559549223 | O7: 2006548179 | P7: 1842394345 | Q7: 162861385 | R7: 19759837 | S7: 1345 | T7: 1403
A8: BANCO BRADESCO S.A. | B8: 60746948 | C8: BRADESCO - PRUDENCIAL | D8: C0010045 | E8: C0080075 | F8: b1 | G8: 2 | H8: 8 | I8: OSASCO | J8: SP | K8: 06/2026 | L8: 1952464273 | M8: 756014814 | N8: 322119751 | O8: 1777233946 | P8: 1545720299 | Q8: 175230327 | R8: 12080064 | S8: 2026 | T8: 762
A9: BANCO SANTANDER (BRASIL) S.A. | B9: 90400888 | C9: SANTANDER - PRUDENCIAL | D9: C0030379 | E9: C0080185 | F9: b1 | G9: 3 | H9: 8 | I9: SAO PAULO | J9: SP | K9: 06/2026 | L9: 1209443083 | M9: 365285710 | N9: 260716671 | O9: 1110706856 | P9: 953249578 | Q9: 98736227 | R9: 7382760 | S9: 1196 | T9: 2516
A10: BANCO NACIONAL DE DESENVOLVIMENTO ECONOMICO E SOCIAL | B10: 33657248 | C10: BNDES - PRUDENCIAL | E10: C0081847 | F10: b4 | G10: 1 | H10: 4 | I10: RIO DE JANEIRO | J10: RJ | K10: 06/2026 | L10: 1073403746 | M10: 375703869 | N10: 209161034 | O10: 892700475 | P10: 661452493 | Q10: 180703272 | R10: 11153448 | S10: 5 | T10: 0
A11: BANCO BTG PACTUAL S.A. | B11: 30306294 | C11: BTG PACTUAL - PRUDENCIAL | D11: C0049944 | E11: C0080336 | F11: b1 | G11: 2 | H11: 8 | I11: RIO DE JANEIRO | J11: RJ | K11: 06/2026 | L11: 743258957 | M11: 81617597 | N11: 228588076 | O11: 663705470 | P11: 548000573 | Q11: 79553487 | R11: 9471540 | S11: 28 | T11: 0
A12: ITAÚ UNIBANCO HOLDING S.A. | B12: 60872504 | C12: ITAU - PRUDENCIAL | D12: C0010069 | E12: C0080099 | F12: b2 | G12: 2 | H12: 8 | I12: SAO PAULO | J12: SP | K12: 06/2026 | L12: 493183395 | M12: 172877389 | N12: 41855441 | O12: 285535078 | P12: 107861159 | Q12: 207648317 | R12: 23205024 | S12: 2 | T12: 7
A13: NU FINANCEIRA S.A. - SOCIEDADE DE CRÉDITO, FINANCIAMENTO E INVESTIMENTO | B13: 30680829 | C13: NU PAGAMENTOS - PRUDENCIAL | D13: C0052058 | E13: C0084693 | F13: n1 | G13: 3 | H13: 14 | I13: SAO PAULO | J13: SP | K13: 06/2026 | L13: 267624695 | M13: 76080601 | N13: 80369899 | O13: 252606112 | P13: 225759535 | Q13: 15018583 | R13: 4194823 | S13: 2 | T13: 0
A14: BANCO SAFRA S.A. | B14: 58160789 | C14: SAFRA - PRUDENCIAL | D14: C0010083 | E14: C0080109 | F14: b1 | G14: 2 | H14: 8 | I14: SAO PAULO | J14: SP | K14: 06/2026 | L14: 256683465 | M14: 93167603 | N14: 46773165 | O14: 238676254 | P14: 204635211 | Q14: 18007212 | R14: 1885083 | S14: 133 | T14: 3
A15: BANCO COOPERATIVO SICREDI S.A. | B15: 1181521 | C15: BCO COOPERATIVO SICREDI - PRUDENCIAL | E15: C0080745 | F15: b1 | G15: 2 | H15: 11 | I15: PORTO ALEGRE | J15: RS | K15: 06/2026 | L15: 234406077 | M15: 50267293 | N15: 49289841 | O15: 228925803 | P15: 202089776 | Q15: 5480274 | R15: 162608 | S15: 6 | T15: 0
A16: BANCO COOPERATIVO SICOOB S.A. - BANCO SICOOB | B16: 2038232 | C16: BANCO SICOOB - PRUDENCIAL | D16: C0051750 | E16: C0080879 | F16: b1 | G16: 2 | H16: 11 | I16: BRASILIA | J16: DF | K16: 06/2026 | L16: 223159409 | M16: 44908980 | N16: 68401403 | O16: 216175011 | P16: 188203009 | Q16: 6984398 | R16: 458952 | S16: 5 | T16: 0
A17: BANCO XP S.A. | B17: 33264668 | C17: XP - PRUDENCIAL | D17: C0052120 | E17: C0082475 | F17: b1 | G17: 2 | H17: 8 | I17: RIO DE JANEIRO | J17: RJ | K17: 06/2026 | L17: 221732251 | M17: 32257267 | N17: 75852463 | O17: 209296234 | P17: 169190938 | Q17: 12436018 | R17: 366732 | S17: 2 | T17: 0
A18: REDECARD INSTITUIÇÃO DE PAGAMENTO S.A. | B18: 1425787 | C18: ITAU - PRUDENCIAL | E18: C0080099 | F18: n4 | G18: 2 | H18: 41 | I18: SAO PAULO | J18: SP | K18: 06/2026 | L18: 178389094 | M18: 0 | N18: 18863330 | O18: 137181221 | P18: 16821616 | Q18: 41207873 | R18: 1497264 | S18: 1 | T18: 0
A19: BANCO DO ESTADO DO RIO GRANDE DO SUL S.A. | B19: 92702067 | C19: BANRISUL - PRUDENCIAL | D19: C0030173 | E19: C0080154 | F19: b1 | G19: 1 | H19: 8 | I19: PORTO ALEGRE | J19: RS | K19: 06/2026 | L19: 172827959 | M19: 60414676 | N19: 75506552 | O19: 161276935 | P19: 150456265 | Q19: 11551023 | R19: 546547 | S19: 506 | T19: 43
A20: BANCO CITIBANK S.A. | B20: 33479023 | C20: CITIBANK - PRUDENCIAL | D20: C0030403 | E20: C0080192 | F20: b1 | G20: 3 | H20: 8 | I20: SAO PAULO | J20: SP | K20: 06/2026 | L20: 169403341 | M20: 26037160 | N20: 46301711 | O20: 164218702 | P20: 145825012 | Q20: 5184639 | R20: 880369 | S20: 44 | T20: 8
A21: BANCO VOTORANTIM S.A. | B21: 59588111 | C21: VOTORANTIM - PRUDENCIAL | D21: C0051011 | E21: C0080484 | F21: b1 | G21: 2 | H21: 8 | I21: SAO PAULO | J21: SP | K21: 06/2026 | L21: 147547552 | M21: 71981491 | N21: 32816913 | O21: 134575200 | P21: 111045483 | Q21: 12972352 | R21: 961452 | S21: 4 | T21: 3
A22: XP INVESTIMENTOS CORRETORA DE CÂMBIO,TÍTULOS E VALORES MOBILIÁRIOS S/A | B22: 2332886 | C22: XP - PRUDENCIAL | D22: C0052120 | E22: C0082475 | F22: n2 | G22: 2 | H22: 15 | I22: RIO DE JANEIRO | J22: RJ | K22: 06/2026 | L22: 132450653 | M22: 147006 | N22: 39754591 | O22: 125124019 | P22: 91424497 | Q22: 7326634 | R22: -40139 | S22: 5 | T22: 0
A23: NU PAGAMENTOS S.A. - INSTITUIÇÃO DE PAGAMENTO | B23: 18236120 | C23: NU PAGAMENTOS - PRUDENCIAL | E23: C0084693 | F23: n4 | G23: 3 | H23: 41 | I23: SAO PAULO | J23: SP | K23: 06/2026 | L23: 122363230 | M23: 75801555 | N23: 684426 | O23: 99117282 | P23: 3084398 | Q23: 23245948 | R23: 4093013 | S23: 1 | T23: 0
A24: BANCO C6 S.A. | B24: 31872495 | C24: BANCO C6 - PRUDENCIAL | D24: C0052072 | E24: C0084844 | F24: b1 | G24: 2 | H24: 8 | I24: SAO PAULO | J24: SP | K24: 06/2026 | L24: 117193733 | M24: 52508241 | N24: 43492491 | O24: 114382052 | P24: 87601269 | Q24: 2811681 | R24: 662077 | S24: 2 | T24: 0
A25: CIELO S.A. - INSTITUIÇÃO DE PAGAMENTO | B25: 1027058 | C25: CIELO IP - PRUDENCIAL | E25: C0084710 | F25: n4 | G25: 2 | H25: 41 | I25: BARUERI | J25: SP | K25: 06/2026 | L25: 116680888 | M25: 0 | N25: 6134397 | O25: 105006218 | P25: 10367314 | Q25: 11674670 | R25: 566759 | S25: 1 | T25: 0
A26: BANCO J.P. MORGAN S.A. | B26: 33172537 | C26: JP MORGAN CHASE - PRUDENCIAL | D26: C0020107 | E26: C0080116 | F26: b1 | G26: 3 | H26: 8 | I26: SAO PAULO | J26: SP | K26: 06/2026 | L26: 110025345 | M26: 3735715 | N26: 62256458 | O26: 98253022 | P26: 84833031 | Q26: 11772323 | R26: 1038284 | S26: 3 | T26: 0
A27: MERCADO PAGO INSTITUIÇÃO DE PAGAMENTO LTDA. | B27: 10573521 | C27: MERCADO PAGO IP - PRUDENCIAL | E27: C0084820 | F27: n4 | G27: 3 | H27: 41 | I27: OSASCO | J27: SP | K27: 06/2026 | L27: 105731564 | M27: 22485259 | N27: 1505659 | O27: 102742356 | P27: 59815921 | Q27: 2989208 | R27: -189822 | S27: 1 | T27: 0
A28: BANCO INTER S.A. | B28: 416968 | C28: INTER - PRUDENCIAL | D28: C0051884 | E28: C0080996 | F28: b1 | G28: 2 | H28: 8 | I28: BELO HORIZONTE | J28: MG | K28: 06/2026 | L28: 100898332 | M28: 46141022 | N28: 28722089 | O28: 93446498 | P28: 77773587 | Q28: 7451834 | R28: 712041 | S28: 2 | T28: 0
A29: BANCO DAYCOVAL S.A. | B29: 62232889 | C29: BCO DAYCOVAL S.A - PRUDENCIAL | D29: C0051987 | E29: C0081744 | F29: b1 | G29: 2 | H29: 8 | I29: SAO PAULO | J29: SP | K29: 06/2026 | L29: 99778656 | M29: 53810851 | N29: 24713706 | O29: 92122935 | P29: 82698919 | Q29: 7655721 | R29: 901621 | S29: 53 | T29: 0
A30: SANTANDER SOCIEDADE DE CRÉDITO, FINANCIAMENTO E INVESTIMENTO S.A. | B30: 7707650 | C30: SANTANDER - PRUDENCIAL | D30: C0030379 | E30: C0080185 | F30: n1 | G30: 3 | H30: 14 | I30: SAO PAULO | J30: SP | K30: 06/2026 | L30: 94908733 | M30: 78916545 | N30: 8626164 | O30: 90101084 | P30: 84719722 | Q30: 4807649 | R30: 361088 | S30: 1 | T30: 0
A31: STONE INSTITUIÇÃO DE PAGAMENTO S.A. | B31: 16501555 | C31: STONE IP - PRUDENCIAL | E31: C0084686 | F31: n4 | G31: 3 | H31: 41 | I31: SAO PAULO | J31: SP | K31: 06/2026 | L31: 89229885 | M31: 0 | N31: 33856104 | O31: 86020632 | P31: 35329072 | Q31: 3209254 | R31: 867035 | S31: 1 | T31: 0
A32: BANCO DO NORDESTE DO BRASIL S.A. | B32: 7237373 | C32: BCO DO NORDESTE DO BRASIL S.A. - PRUDENCIAL | E32: C0081593 | F32: b1 | G32: 1 | H32: 8 | I32: FORTALEZA | J32: CE | K32: 06/2026 | L32: 81039783 | M32: 17779920 | N32: 44768452 | O32: 64226772 | P32: 23269171 | Q32: 16813010 | R32: 1057412 | S32: 301 | T32: 1
A33: BANCO PAN S.A. | B33: 59285411 | C33: BTG PACTUAL - PRUDENCIAL | D33: C0049944 | E33: C0080336 | F33: b1 | G33: 2 | H33: 8 | I33: RIO DE JANEIRO | J33: RJ | K33: 06/2026 | L33: 77255474 | M33: 35566859 | N33: 24319234 | O33: 68495128 | P33: 64315922 | Q33: 8760346 | R33: 689725 | S33: 2 | T33: 0
A34: GETNET ADQUIRÊNCIA E SERVIÇOS PARA MEIOS DE PAGAMENTO S.A. INSTITUIÇÃO DE PAGAMENTO | B34: 10440482 | C34: SANTANDER - PRUDENCIAL | E34: C0080185 | F34: n4 | G34: 3 | H34: 41 | I34: SAO PAULO | J34: SP | K34: 06/2026 | L34: 74198667 | M34: 0 | N34: 471650 | O34: 70373351 | P34: 457227 | Q34: 3825316 | R34: 529101 | S34: 1 | T34: 0
A35: PAGSEGURO INTERNET INSTITUIÇÃO DE PAGAMENTO S.A. | B35: 8561701 | C35: PAGSEGURO - PRUDENCIAL | E35: C0084813 | F35: n4 | G35: 2 | H35: 41 | I35: SAO PAULO | J35: SP | K35: 06/2026 | L35: 73530147 | M35: 746551 | N35: 5259611 | O35: 67499312 | P35: 46766864 | Q35: 6030835 | R35: 463519 | S35: 1 | T35: 0
A36: BANCO BRADESCO FINANCIAMENTOS S.A. | B36: 7207996 | C36: BRADESCO - PRUDENCIAL | D36: C0010045 | E36: C0080075 | F36: b1 | G36: 2 | H36: 8 | I36: OSASCO | J36: SP | K36: 06/2026 | L36: 68748096 | M36: 52483412 | N36: 60748 | O36: 68114489 | P36: 65248099 | Q36: 633608 | R36: 12331 | S36: 2 | T36: 5
A37: BANCO DA AMAZONIA S.A. | B37: 4902979 | C37: BCO DA AMAZONIA S.A. - PRUDENCIAL | E37: C0081249 | F37: b1 | G37: 1 | H37: 2 | I37: BELEM | J37: PA | K37: 06/2026 | L37: 67352881 | M37: 38713829 | N37: 21699434 | O37: 60078810 | P37: 15601132 | Q37: 7274071 | R37: 353060 | S37: 115 | T37: 0
A38: BANCO ABC BRASIL S.A. | B38: 28195667 | C38: ABC-BRASIL - PRUDENCIAL | D38: C0041856 | E38: C0080312 | F38: b1 | G38: 3 | H38: 8 | I38: SAO PAULO | J38: SP | K38: 06/2026 | L38: 66147427 | M38: 18520743 | N38: 29173812 | O38: 58888511 | P38: 50226679 | Q38: 7258915 | R38: 487535 | S38: 13 | T38: 0
A39: BANCO VOLKSWAGEN S.A. | B39: 59109165 | C39: VOLKSWAGEN - PRUDENCIAL | E39: C0080202 | F39: b2 | G39: 3 | H39: 8 | I39: SAO PAULO | J39: SP | K39: 06/2026 | L39: 61250495 | M39: 50345582 | N39: 819927 | O39: 55986251 | P39: 47916041 | Q39: 5264244 | R39: -203091 | S39: 2 | T39: 0
A40: BANCO BNP PARIBAS BRASIL S.A. | B40: 1522368 | C40: BNP PARIBAS - PRUDENCIAL | E40: C0080673 | F40: b1 | G40: 3 | H40: 8 | I40: SAO PAULO | J40: SP | K40: 06/2026 | L40: 58787929 | M40: 6716037 | N40: 21646070 | O40: 54077310 | P40: 34516225 | Q40: 4710619 | R40: 86546 | S40: 2 | T40: 0
A41: BANCO C6 CONSIGNADO S.A. | B41: 61348538 | C41: BANCO C6 - PRUDENCIAL | D41: C0052072 | E41: C0084844 | F41: b1 | G41: 2 | H41: 8 | I41: SAO PAULO | J41: SP | K41: 06/2026 | L41: 56164263 | M41: 42537256 | N41: 7432727 | O41: 52511688 | P41: 39443515 | Q41: 3652575 | R41: 559375 | S41: 2 | T41: 0
...

Sheet Base_IFData
A1: BASE DE DADOS | IFData Junho 2026
A2: Fonte: IF.data, Banco Central do Brasil (https://www3.bcb.gov.br/ifdata)
A4: Instituição | B4: Código | C4: Conglomerado Prudencial (Nome) | D4: Conglomerado Financeiro (Cód.) | E4: Conglomerado Prudencial (Cód.) | F4: TCB | G4: TC | H4: TI | I4: Cidade | J4: UF | K4: Data | L4: Ativo Total (R$ mil) | M4: Carteira de Crédito (R$ mil) | N4: Títulos e Valores Mobiliários (R$ mil) | O4: Passivo Exigível (R$ mil) | P4: Captações (R$ mil) | Q4: Patrimônio Líquido (R$ mil) | R4: Lucro Líquido (R$ mil) | S4: Número de Agências | T4: Postos de Atendimento | U4: Tipo de Controle | V4: Índice Crédito/Ativo | W4: ROE do semestre | X4: Porte | Y4: Classe ROE
A5: BANCO DO BRASIL S.A. | B5: 0 | C5: BB - PRUDENCIAL | D5: C0049906 | E5: C0080329 | F5: b1 | G5: 1 | H5: 1 | I5: BRASILIA | J5: DF | K5: 06/2026 | L5: 2461086914 | M5: 1065710905 | N5: 714731784 | O5: 2279753810 | P5: 1974660924 | Q5: 181333105 | R5: 6216056 | S5: 3932 | T5: 309 | U5: =IFERROR(CHOOSE(G5,"Público","Privado Nacional","Privado Estrangeiro"),"n.d.") -> Público | V5: =IF(AND(ISNUMBER(M5),ISNUMBER(L5)),IF(L5>0,M5/L5,"n.d."),"NI") -> 0.43302449 | W5: =IF(AND(ISNUMBER(R5),ISNUMBER(Q5)),IF(Q5>0,R5/Q5,"n.d."),"NI") -> 0.034279764 | X5: =IF(ISNUMBER(L5),IF(L5>100000000,"Grande","Média/Pequena"),"Sem dado") -> Grande | Y5: {=_xlfn.IFS(ISNUMBER(W5)=FALSE,"Sem dado",W5>0.075,"Excelente",W5>0.04,"Bom",W5>0,"Fraco",TRUE,"Prejuízo")} -> Fraco
A6: CAIXA ECONOMICA FEDERAL | B6: 360305 | C6: CAIXA ECONÔMICA FEDERAL - PRUDENCIAL | D6: C0051626 | E6: C0080738 | F6: b1 | G6: 1 | H6: 6 | I6: BRASILIA | J6: DF | K6: 06/2026 | L6: 2368147225 | M6: 1362330927 | N6: 452416774 | O6: 2249779433 | P6: 2063880327 | Q6: 118367792 | R6: 6585794 | S6: 3000 | T6: 868 | U6: =IFERROR(CHOOSE(G6,"Público","Privado Nacional","Privado Estrangeiro"),"n.d.") -> Público | V6: =IF(AND(ISNUMBER(M6),ISNUMBER(L6)),IF(L6>0,M6/L6,"n.d."),"NI") -> 0.5752729 | W6: =IF(AND(ISNUMBER(R6),ISNUMBER(Q6)),IF(Q6>0,R6/Q6,"n.d."),"NI") -> 0.055638395 | X6: =IF(ISNUMBER(L6),IF(L6>100000000,"Grande","Média/Pequena"),"Sem dado") -> Grande | Y6: {=_xlfn.IFS(ISNUMBER(W6)=FALSE,"Sem dado",W6>0.075,"Excelente",W6>0.04,"Bom",W6>0,"Fraco",TRUE,"Prejuízo")} -> Bom
A7: ITAÚ UNIBANCO S.A. | B7: 60701190 | C7: ITAU - PRUDENCIAL | D7: C0010069 | E7: C0080099 | F7: b1 | G7: 2 | H7: 8 | I7: SAO PAULO | J7: SP | K7: 06/2026 | L7: 2169409565 | M7: 700105223 | N7: 559549223 | O7: 2006548179 | P7: 1842394345 | Q7: 162861385 | R7: 19759837 | S7: 1345 | T7: 1403 | U7: =IFERROR(CHOOSE(G7,"Público","Privado Nacional","Privado Estrangeiro"),"n.d.") -> Privado Nacional | V7: =IF(AND(ISNUMBER(M7),ISNUMBER(L7)),IF(L7>0,M7/L7,"n.d."),"NI") -> 0.32271694 | W7: =IF(AND(ISNUMBER(R7),ISNUMBER(Q7)),IF(Q7>0,R7/Q7,"n.d."),"NI") -> 0.12132917 | X7: =IF(ISNUMBER(L7),IF(L7>100000000,"Grande","Média/Pequena"),"Sem dado") -> Grande | Y7: {=_xlfn.IFS(ISNUMBER(W7)=FALSE,"Sem dado",W7>0.075,"Excelente",W7>0.04,"Bom",W7>0,"Fraco",TRUE,"Prejuízo")} -> Excelente
A8: BANCO BRADESCO S.A. | B8: 60746948 | C8: BRADESCO - PRUDENCIAL | D8: C0010045 | E8: C0080075 | F8: b1 | G8: 2 | H8: 8 | I8: OSASCO | J8: SP | K8: 06/2026 | L8: 1952464273 | M8: 756014814 | N8: 322119751 | O8: 1777233946 | P8: 1545720299 | Q8: 175230327 | R8: 12080064 | S8: 2026 | T8: 762 | U8: =IFERROR(CHOOSE(G8,"Público","Privado Nacional","Privado Estrangeiro"),"n.d.") -> Privado Nacional | V8: =IF(AND(ISNUMBER(M8),ISNUMBER(L8)),IF(L8>0,M8/L8,"n.d."),"NI") -> 0.38721058 | W8: =IF(AND(ISNUMBER(R8),ISNUMBER(Q8)),IF(Q8>0,R8/Q8,"n.d."),"NI") -> 0.068938204 | X8: =IF(ISNUMBER(L8),IF(L8>100000000,"Grande","Média/Pequena"),"Sem dado") -> Grande | Y8: {=_xlfn.IFS(ISNUMBER(W8)=FALSE,"Sem dado",W8>0.075,"Excelente",W8>0.04,"Bom",W8>0,"Fraco",TRUE,"Prejuízo")} -> Bom
A9: BANCO SANTANDER (BRASIL) S.A. | B9: 90400888 | C9: SANTANDER - PRUDENCIAL | D9: C0030379 | E9: C0080185 | F9: b1 | G9: 3 | H9: 8 | I9: SAO PAULO | J9: SP | K9: 06/2026 | L9: 1209443083 | M9: 365285710 | N9: 260716671 | O9: 1110706856 | P9: 953249578 | Q9: 98736227 | R9: 7382760 | S9: 1196 | T9: 2516 | U9: =IFERROR(CHOOSE(G9,"Público","Privado Nacional","Privado Estrangeiro"),"n.d.") -> Privado Estrangeiro | V9: =IF(AND(ISNUMBER(M9),ISNUMBER(L9)),IF(L9>0,M9/L9,"n.d."),"NI") -> 0.30202803 | W9: =IF(AND(ISNUMBER(R9),ISNUMBER(Q9)),IF(Q9>0,R9/Q9,"n.d."),"NI") -> 0.074772555 | X9: =IF(ISNUMBER(L9),IF(L9>100000000,"Grande","Média/Pequena"),"Sem dado") -> Grande | Y9: {=_xlfn.IFS(ISNUMBER(W9)=FALSE,"Sem dado",W9>0.075,"Excelente",W9>0.04,"Bom",W9>0,"Fraco",TRUE,"Prejuízo")} -> Bom
A10: BANCO NACIONAL DE DESENVOLVIMENTO ECONOMICO E SOCIAL | B10: 33657248 | C10: BNDES - PRUDENCIAL | E10: C0081847 | F10: b4 | G10: 1 | H10: 4 | I10: RIO DE JANEIRO | J10: RJ | K10: 06/2026 | L10: 1073403746 | M10: 375703869 | N10: 209161034 | O10: 892700475 | P10: 661452493 | Q10: 180703272 | R10: 11153448 | S10: 5 | T10: 0 | U10: =IFERROR(CHOOSE(G10,"Público","Privado Nacional","Privado Estrangeiro"),"n.d.") -> Público | V10: =IF(AND(ISNUMBER(M10),ISNUMBER(L10)),IF(L10>0,M10/L10,"n.d."),"NI") -> 0.3500117 | W10: =IF(AND(ISNUMBER(R10),ISNUMBER(Q10)),IF(Q10>0,R10/Q10,"n.d."),"NI") -> 0.061722446 | X10: =IF(ISNUMBER(L10),IF(L10>100000000,"Grande","Média/Pequena"),"Sem dado") -> Grande | Y10: {=_xlfn.IFS(ISNUMBER(W10)=FALSE,"Sem dado",W10>0.075,"Excelente",W10>0.04,"Bom",W10>0,"Fraco",TRUE,"Prejuízo")} -> Bom
A11: BANCO BTG PACTUAL S.A. | B11: 30306294 | C11: BTG PACTUAL - PRUDENCIAL | D11: C0049944 | E11: C0080336 | F11: b1 | G11: 2 | H11: 8 | I11: RIO DE JANEIRO | J11: RJ | K11: 06/2026 | L11: 743258957 | M11: 81617597 | N11: 228588076 | O11: 663705470 | P11: 548000573 | Q11: 79553487 | R11: 9471540 | S11: 28 | T11: 0 | U11: =IFERROR(CHOOSE(G11,"Público","Privado Nacional","Privado Estrangeiro"),"n.d.") -> Privado Nacional | V11: =IF(AND(ISNUMBER(M11),ISNUMBER(L11)),IF(L11>0,M11/L11,"n.d."),"NI") -> 0.10981045 | W11: =IF(AND(ISNUMBER(R11),ISNUMBER(Q11)),IF(Q11>0,R11/Q11,"n.d."),"NI") -> 0.11905877 | X11: =IF(ISNUMBER(L11),IF(L11>100000000,"Grande","Média/Pequena"),"Sem dado") -> Grande | Y11: {=_xlfn.IFS(ISNUMBER(W11)=FALSE,"Sem dado",W11>0.075,"Excelente",W11>0.04,"Bom",W11>0,"Fraco",TRUE,"Prejuízo")} -> Excelente
A12: ITAÚ UNIBANCO HOLDING S.A. | B12: 60872504 | C12: ITAU - PRUDENCIAL | D12: C0010069 | E12: C0080099 | F12: b2 | G12: 2 | H12: 8 | I12: SAO PAULO | J12: SP | K12: 06/2026 | L12: 493183395 | M12: 172877389 | N12: 41855441 | O12: 285535078 | P12: 107861159 | Q12: 207648317 | R12: 23205024 | S12: 2 | T12: 7 | U12: =IFERROR(CHOOSE(G12,"Público","Privado Nacional","Privado Estrangeiro"),"n.d.") -> Privado Nacional | V12: =IF(AND(ISNUMBER(M12),ISNUMBER(L12)),IF(L12>0,M12/L12,"n.d."),"NI") -> 0.35053368 | W12: =IF(AND(ISNUMBER(R12),ISNUMBER(Q12)),IF(Q12>0,R12/Q12,"n.d."),"NI") -> 0.11175156 | X12: =IF(ISNUMBER(L12),IF(L12>100000000,"Grande","Média/Pequena"),"Sem dado") -> Grande | Y12: {=_xlfn.IFS(ISNUMBER(W12)=FALSE,"Sem dado",W12>0.075,"Excelente",W12>0.04,"Bom",W12>0,"Fraco",TRUE,"Prejuízo")} -> Excelente
A13: NU FINANCEIRA S.A. - SOCIEDADE DE CRÉDITO, FINANCIAMENTO E INVESTIMENTO | B13: 30680829 | C13: NU PAGAMENTOS - PRUDENCIAL | D13: C0052058 | E13: C0084693 | F13: n1 | G13: 3 | H13: 14 | I13: SAO PAULO | J13: SP | K13: 06/2026 | L13: 267624695 | M13: 76080601 | N13: 80369899 | O13: 252606112 | P13: 225759535 | Q13: 15018583 | R13: 4194823 | S13: 2 | T13: 0 | U13: =IFERROR(CHOOSE(G13,"Público","Privado Nacional","Privado Estrangeiro"),"n.d.") -> Privado Estrangeiro | V13: =IF(AND(ISNUMBER(M13),ISNUMBER(L13)),IF(L13>0,M13/L13,"n.d."),"NI") -> 0.28428094 | W13: =IF(AND(ISNUMBER(R13),ISNUMBER(Q13)),IF(Q13>0,R13/Q13,"n.d."),"NI") -> 0.27930884 | X13: =IF(ISNUMBER(L13),IF(L13>100000000,"Grande","Média/Pequena"),"Sem dado") -> Grande | Y13: {=_xlfn.IFS(ISNUMBER(W13)=FALSE,"Sem dado",W13>0.075,"Excelente",W13>0.04,"Bom",W13>0,"Fraco",TRUE,"Prejuízo")} -> Excelente
A14: BANCO SAFRA S.A. | B14: 58160789 | C14: SAFRA - PRUDENCIAL | D14: C0010083 | E14: C0080109 | F14: b1 | G14: 2 | H14: 8 | I14: SAO PAULO | J14: SP | K14: 06/2026 | L14: 256683465 | M14: 93167603 | N14: 46773165 | O14: 238676254 | P14: 204635211 | Q14: 18007212 | R14: 1885083 | S14: 133 | T14: 3 | U14: =IFERROR(CHOOSE(G14,"Público","Privado Nacional","Privado Estrangeiro"),"n.d.") -> Privado Nacional | V14: =IF(AND(ISNUMBER(M14),ISNUMBER(L14)),IF(L14>0,M14/L14,"n.d."),"NI") -> 0.36296691 | W14: =IF(AND(ISNUMBER(R14),ISNUMBER(Q14)),IF(Q14>0,R14/Q14,"n.d."),"NI") -> 0.10468489 | X14: =IF(ISNUMBER(L14),IF(L14>100000000,"Grande","Média/Pequena"),"Sem dado") -> Grande | Y14: {=_xlfn.IFS(ISNUMBER(W14)=FALSE,"Sem dado",W14>0.075,"Excelente",W14>0.04,"Bom",W14>0,"Fraco",TRUE,"Prejuízo")} -> Excelente
A15: BANCO COOPERATIVO SICREDI S.A. | B15: 1181521 | C15: BCO COOPERATIVO SICREDI - PRUDENCIAL | E15: C0080745 | F15: b1 | G15: 2 | H15: 11 | I15: PORTO ALEGRE | J15: RS | K15: 06/2026 | L15: 234406077 | M15: 50267293 | N15: 49289841 | O15: 228925803 | P15: 202089776 | Q15: 5480274 | R15: 162608 | S15: 6 | T15: 0 | U15: =IFERROR(CHOOSE(G15,"Público","Privado Nacional","Privado Estrangeiro"),"n.d.") -> Privado Nacional | V15: =IF(AND(ISNUMBER(M15),ISNUMBER(L15)),IF(L15>0,M15/L15,"n.d."),"NI") -> 0.21444535 | W15: =IF(AND(ISNUMBER(R15),ISNUMBER(Q15)),IF(Q15>0,R15/Q15,"n.d."),"NI") -> 0.029671509 | X15: =IF(ISNUMBER(L15),IF(L15>100000000,"Grande","Média/Pequena"),"Sem dado") -> Grande | Y15: {=_xlfn.IFS(ISNUMBER(W15)=FALSE,"Sem dado",W15>0.075,"Excelente",W15>0.04,"Bom",W15>0,"Fraco",TRUE,"Prejuízo")} -> Fraco
A16: BANCO COOPERATIVO SICOOB S.A. - BANCO SICOOB | B16: 2038232 | C16: BANCO SICOOB - PRUDENCIAL | D16: C0051750 | E16: C0080879 | F16: b1 | G16: 2 | H16: 11 | I16: BRASILIA | J16: DF | K16: 06/2026 | L16: 223159409 | M16: 44908980 | N16: 68401403 | O16: 216175011 | P16: 188203009 | Q16: 6984398 | R16: 458952 | S16: 5 | T16: 0 | U16: =IFERROR(CHOOSE(G16,"Público","Privado Nacional","Privado Estrangeiro"),"n.d.") -> Privado Nacional | V16: =IF(AND(ISNUMBER(M16),ISNUMBER(L16)),IF(L16>0,M16/L16,"n.d."),"NI") -> 0.20124171 | W16: =IF(AND(ISNUMBER(R16),ISNUMBER(Q16)),IF(Q16>0,R16/Q16,"n.d."),"NI") -> 0.065711032 | X16: =IF(ISNUMBER(L16),IF(L16>100000000,"Grande","Média/Pequena"),"Sem dado") -> Grande | Y16: {=_xlfn.IFS(ISNUMBER(W16)=FALSE,"Sem dado",W16>0.075,"Excelente",W16>0.04,"Bom",W16>0,"Fraco",TRUE,"Prejuízo")} -> Bom
A17: BANCO XP S.A. | B17: 33264668 | C17: XP - PRUDENCIAL | D17: C0052120 | E17: C0082475 | F17: b1 | G17: 2 | H17: 8 | I17: RIO DE JANEIRO | J17: RJ | K17: 06/2026 | L17: 221732251 | M17: 32257267 | N17: 75852463 | O17: 209296234 | P17: 169190938 | Q17: 12436018 | R17: 366732 | S17: 2 | T17: 0 | U17: =IFERROR(CHOOSE(G17,"Público","Privado Nacional","Privado Estrangeiro"),"n.d.") -> Privado Nacional | V17: =IF(AND(ISNUMBER(M17),ISNUMBER(L17)),IF(L17>0,M17/L17,"n.d."),"NI") -> 0.14547846 | W17: =IF(AND(ISNUMBER(R17),ISNUMBER(Q17)),IF(Q17>0,R17/Q17,"n.d."),"NI") -> 0.029489504 | X17: =IF(ISNUMBER(L17),IF(L17>100000000,"Grande","Média/Pequena"),"Sem dado") -> Grande | Y17: {=_xlfn.IFS(ISNUMBER(W17)=FALSE,"Sem dado",W17>0.075,"Excelente",W17>0.04,"Bom",W17>0,"Fraco",TRUE,"Prejuízo")} -> Fraco
A18: REDECARD INSTITUIÇÃO DE PAGAMENTO S.A. | B18: 1425787 | C18: ITAU - PRUDENCIAL | E18: C0080099 | F18: n4 | G18: 2 | H18: 41 | I18: SAO PAULO | J18: SP | K18: 06/2026 | L18: 178389094 | M18: 0 | N18: 18863330 | O18: 137181221 | P18: 16821616 | Q18: 41207873 | R18: 1497264 | S18: 1 | T18: 0 | U18: =IFERROR(CHOOSE(G18,"Público","Privado Nacional","Privado Estrangeiro"),"n.d.") -> Privado Nacional | V18: =IF(AND(ISNUMBER(M18),ISNUMBER(L18)),IF(L18>0,M18/L18,"n.d."),"NI") -> 0 | W18: =IF(AND(ISNUMBER(R18),ISNUMBER(Q18)),IF(Q18>0,R18/Q18,"n.d."),"NI") -> 0.036334416 | X18: =IF(ISNUMBER(L18),IF(L18>100000000,"Grande","Média/Pequena"),"Sem dado") -> Grande | Y18: {=_xlfn.IFS(ISNUMBER(W18)=FALSE,"Sem dado",W18>0.075,"Excelente",W18>0.04,"Bom",W18>0,"Fraco",TRUE,"Prejuízo")} -> Fraco
A19: BANCO DO ESTADO DO RIO GRANDE DO SUL S.A. | B19: 92702067 | C19: BANRISUL - PRUDENCIAL | D19: C0030173 | E19: C0080154 | F19: b1 | G19: 1 | H19: 8 | I19: PORTO ALEGRE | J19: RS | K19: 06/2026 | L19: 172827959 | M19: 60414676 | N19: 75506552 | O19: 161276935 | P19: 150456265 | Q19: 11551023 | R19: 546547 | S19: 506 | T19: 43 | U19: =IFERROR(CHOOSE(G19,"Público","Privado Nacional","Privado Estrangeiro"),"n.d.") -> Público | V19: =IF(AND(ISNUMBER(M19),ISNUMBER(L19)),IF(L19>0,M19/L19,"n.d."),"NI") -> 0.34956541 | W19: =IF(AND(ISNUMBER(R19),ISNUMBER(Q19)),IF(Q19>0,R19/Q19,"n.d."),"NI") -> 0.047315896 | X19: =IF(ISNUMBER(L19),IF(L19>100000000,"Grande","Média/Pequena"),"Sem dado") -> Grande | Y19: {=_xlfn.IFS(ISNUMBER(W19)=FALSE,"Sem dado",W19>0.075,"Excelente",W19>0.04,"Bom",W19>0,"Fraco",TRUE,"Prejuízo")} -> Bom
A20: BANCO CITIBANK S.A. | B20: 33479023 | C20: CITIBANK - PRUDENCIAL | D20: C0030403 | E20: C0080192 | F20: b1 | G20: 3 | H20: 8 | I20: SAO PAULO | J20: SP | K20: 06/2026 | L20: 169403341 | M20: 26037160 | N20: 46301711 | O20: 164218702 | P20: 145825012 | Q20: 5184639 | R20: 880369 | S20: 44 | T20: 8 | U20: =IFERROR(CHOOSE(G20,"Público","Privado Nacional","Privado Estrangeiro"),"n.d.") -> Privado Estrangeiro | V20: =IF(AND(ISNUMBER(M20),ISNUMBER(L20)),IF(L20>0,M20/L20,"n.d."),"NI") -> 0.15369921 | W20: =IF(AND(ISNUMBER(R20),ISNUMBER(Q20)),IF(Q20>0,R20/Q20,"n.d."),"NI") -> 0.16980334 | X20: =IF(ISNUMBER(L20),IF(L20>100000000,"Grande","Média/Pequena"),"Sem dado") -> Grande | Y20: {=_xlfn.IFS(ISNUMBER(W20)=FALSE,"Sem dado",W20>0.075,"Excelente",W20>0.04,"Bom",W20>0,"Fraco",TRUE,"Prejuízo")} -> Excelente
A21: BANCO VOTORANTIM S.A. | B21: 59588111 | C21: VOTORANTIM - PRUDENCIAL | D21: C0051011 | E21: C0080484 | F21: b1 | G21: 2 | H21: 8 | I21: SAO PAULO | J21: SP | K21: 06/2026 | L21: 147547552 | M21: 71981491 | N21: 32816913 | O21: 134575200 | P21: 111045483 | Q21: 12972352 | R21: 961452 | S21: 4 | T21: 3 | U21: =IFERROR(CHOOSE(G21,"Público","Privado Nacional","Privado Estrangeiro"),"n.d.") -> Privado Nacional | V21: =IF(AND(ISNUMBER(M21),ISNUMBER(L21)),IF(L21>0,M21/L21,"n.d."),"NI") -> 0.48785283 | W21: =IF(AND(ISNUMBER(R21),ISNUMBER(Q21)),IF(Q21>0,R21/Q21,"n.d."),"NI") -> 0.074115473 | X21: =IF(ISNUMBER(L21),IF(L21>100000000,"Grande","Média/Pequena"),"Sem dado") -> Grande | Y21: {=_xlfn.IFS(ISNUMBER(W21)=FALSE,"Sem dado",W21>0.075,"Excelente",W21>0.04,"Bom",W21>0,"Fraco",TRUE,"Prejuízo")} -> Bom
A22: XP INVESTIMENTOS CORRETORA DE CÂMBIO,TÍTULOS E VALORES MOBILIÁRIOS S/A | B22: 2332886 | C22: XP - PRUDENCIAL | D22: C0052120 | E22: C0082475 | F22: n2 | G22: 2 | H22: 15 | I22: RIO DE JANEIRO | J22: RJ | K22: 06/2026 | L22: 132450653 | M22: 147006 | N22: 39754591 | O22: 125124019 | P22: 91424497 | Q22: 7326634 | R22: -40139 | S22: 5 | T22: 0 | U22: =IFERROR(CHOOSE(G22,"Público","Privado Nacional","Privado Estrangeiro"),"n.d.") -> Privado Nacional | V22: =IF(AND(ISNUMBER(M22),ISNUMBER(L22)),IF(L22>0,M22/L22,"n.d."),"NI") -> 0.0011098926 | W22: =IF(AND(ISNUMBER(R22),ISNUMBER(Q22)),IF(Q22>0,R22/Q22,"n.d."),"NI") -> -0.0054785049 | X22: =IF(ISNUMBER(L22),IF(L22>100000000,"Grande","Média/Pequena"),"Sem dado") -> Grande | Y22: {=_xlfn.IFS(ISNUMBER(W22)=FALSE,"Sem dado",W22>0.075,"Excelente",W22>0.04,"Bom",W22>0,"Fraco",TRUE,"Prejuízo")} -> Prejuízo
A23: NU PAGAMENTOS S.A. - INSTITUIÇÃO DE PAGAMENTO | B23: 18236120 | C23: NU PAGAMENTOS - PRUDENCIAL | E23: C0084693 | F23: n4 | G23: 3 | H23: 41 | I23: SAO PAULO | J23: SP | K23: 06/2026 | L23: 122363230 | M23: 75801555 | N23: 684426 | O23: 99117282 | P23: 3084398 | Q23: 23245948 | R23: 4093013 | S23: 1 | T23: 0 | U23: =IFERROR(CHOOSE(G23,"Público","Privado Nacional","Privado Estrangeiro"),"n.d.") -> Privado Estrangeiro | V23: =IF(AND(ISNUMBER(M23),ISNUMBER(L23)),IF(L23>0,M23/L23,"n.d."),"NI") -> 0.61947985 | W23: =IF(AND(ISNUMBER(R23),ISNUMBER(Q23)),IF(Q23>0,R23/Q23,"n.d."),"NI") -> 0.17607426 | X23: =IF(ISNUMBER(L23),IF(L23>100000000,"Grande","Média/Pequena"),"Sem dado") -> Grande | Y23: {=_xlfn.IFS(ISNUMBER(W23)=FALSE,"Sem dado",W23>0.075,"Excelente",W23>0.04,"Bom",W23>0,"Fraco",TRUE,"Prejuízo")} -> Excelente
A24: BANCO C6 S.A. | B24: 31872495 | C24: BANCO C6 - PRUDENCIAL | D24: C0052072 | E24: C0084844 | F24: b1 | G24: 2 | H24: 8 | I24: SAO PAULO | J24: SP | K24: 06/2026 | L24: 117193733 | M24: 52508241 | N24: 43492491 | O24: 114382052 | P24: 87601269 | Q24: 2811681 | R24: 662077 | S24: 2 | T24: 0 | U24: =IFERROR(CHOOSE(G24,"Público","Privado Nacional","Privado Estrangeiro"),"n.d.") -> Privado Nacional | V24: =IF(AND(ISNUMBER(M24),ISNUMBER(L24)),IF(L24>0,M24/L24,"n.d."),"NI") -> 0.44804649 | W24: =IF(AND(ISNUMBER(R24),ISNUMBER(Q24)),IF(Q24>0,R24/Q24,"n.d."),"NI") -> 0.23547373 | X24: =IF(ISNUMBER(L24),IF(L24>100000000,"Grande","Média/Pequena"),"Sem dado") -> Grande | Y24: {=_xlfn.IFS(ISNUMBER(W24)=FALSE,"Sem dado",W24>0.075,"Excelente",W24>0.04,"Bom",W24>0,"Fraco",TRUE,"Prejuízo")} -> Excelente
A25: CIELO S.A. - INSTITUIÇÃO DE PAGAMENTO | B25: 1027058 | C25: CIELO IP - PRUDENCIAL | E25: C0084710 | F25: n4 | G25: 2 | H25: 41 | I25: BARUERI | J25: SP | K25: 06/2026 | L25: 116680888 | M25: 0 | N25: 6134397 | O25: 105006218 | P25: 10367314 | Q25: 11674670 | R25: 566759 | S25: 1 | T25: 0 | U25: =IFERROR(CHOOSE(G25,"Público","Privado Nacional","Privado Estrangeiro"),"n.d.") -> Privado Nacional | V25: =IF(AND(ISNUMBER(M25),ISNUMBER(L25)),IF(L25>0,M25/L25,"n.d."),"NI") -> 0 | W25: =IF(AND(ISNUMBER(R25),ISNUMBER(Q25)),IF(Q25>0,R25/Q25,"n.d."),"NI") -> 0.04854604 | X25: =IF(ISNUMBER(L25),IF(L25>100000000,"Grande","Média/Pequena"),"Sem dado") -> Grande | Y25: {=_xlfn.IFS(ISNUMBER(W25)=FALSE,"Sem dado",W25>0.075,"Excelente",W25>0.04,"Bom",W25>0,"Fraco",TRUE,"Prejuízo")} -> Bom
A26: BANCO J.P. MORGAN S.A. | B26: 33172537 | C26: JP MORGAN CHASE - PRUDENCIAL | D26: C0020107 | E26: C0080116 | F26: b1 | G26: 3 | H26: 8 | I26: SAO PAULO | J26: SP | K26: 06/2026 | L26: 110025345 | M26: 3735715 | N26: 62256458 | O26: 98253022 | P26: 84833031 | Q26: 11772323 | R26: 1038284 | S26: 3 | T26: 0 | U26: =IFERROR(CHOOSE(G26,"Público","Privado Nacional","Privado Estrangeiro"),"n.d.") -> Privado Estrangeiro | V26: =IF(AND(ISNUMBER(M26),ISNUMBER(L26)),IF(L26>0,M26/L26,"n.d."),"NI") -> 0.033953222 | W26: =IF(AND(ISNUMBER(R26),ISNUMBER(Q26)),IF(Q26>0,R26/Q26,"n.d."),"NI") -> 0.088197036 | X26: =IF(ISNUMBER(L26),IF(L26>100000000,"Grande","Média/Pequena"),"Sem dado") -> Grande | Y26: {=_xlfn.IFS(ISNUMBER(W26)=FALSE,"Sem dado",W26>0.075,"Excelente",W26>0.04,"Bom",W26>0,"Fraco",TRUE,"Prejuízo")} -> Excelente
A27: MERCADO PAGO INSTITUIÇÃO DE PAGAMENTO LTDA. | B27: 10573521 | C27: MERCADO PAGO IP - PRUDENCIAL | E27: C0084820 | F27: n4 | G27: 3 | H27: 41 | I27: OSASCO | J27: SP | K27: 06/2026 | L27: 105731564 | M27: 22485259 | N27: 1505659 | O27: 102742356 | P27: 59815921 | Q27: 2989208 | R27: -189822 | S27: 1 | T27: 0 | U27: =IFERROR(CHOOSE(G27,"Público","Privado Nacional","Privado Estrangeiro"),"n.d.") -> Privado Estrangeiro | V27: =IF(AND(ISNUMBER(M27),ISNUMBER(L27)),IF(L27>0,M27/L27,"n.d."),"NI") -> 0.21266364 | W27: =IF(AND(ISNUMBER(R27),ISNUMBER(Q27)),IF(Q27>0,R27/Q27,"n.d."),"NI") -> -0.063502439 | X27: =IF(ISNUMBER(L27),IF(L27>100000000,"Grande","Média/Pequena"),"Sem dado") -> Grande | Y27: {=_xlfn.IFS(ISNUMBER(W27)=FALSE,"Sem dado",W27>0.075,"Excelente",W27>0.04,"Bom",W27>0,"Fraco",TRUE,"Prejuízo")} -> Prejuízo
A28: BANCO INTER S.A. | B28: 416968 | C28: INTER - PRUDENCIAL | D28: C0051884 | E28: C0080996 | F28: b1 | G28: 2 | H28: 8 | I28: BELO HORIZONTE | J28: MG | K28: 06/2026 | L28: 100898332 | M28: 46141022 | N28: 28722089 | O28: 93446498 | P28: 77773587 | Q28: 7451834 | R28: 712041 | S28: 2 | T28: 0 | U28: =IFERROR(CHOOSE(G28,"Público","Privado Nacional","Privado Estrangeiro"),"n.d.") -> Privado Nacional | V28: =IF(AND(ISNUMBER(M28),ISNUMBER(L28)),IF(L28>0,M28/L28,"n.d."),"NI") -> 0.45730213 | W28: =IF(AND(ISNUMBER(R28),ISNUMBER(Q28)),IF(Q28>0,R28/Q28,"n.d."),"NI") -> 0.095552451 | X28: =IF(ISNUMBER(L28),IF(L28>100000000,"Grande","Média/Pequena"),"Sem dado") -> Grande | Y28: {=_xlfn.IFS(ISNUMBER(W28)=FALSE,"Sem dado",W28>0.075,"Excelente",W28>0.04,"Bom",W28>0,"Fraco",TRUE,"Prejuízo")} -> Excelente
A29: BANCO DAYCOVAL S.A. | B29: 62232889 | C29: BCO DAYCOVAL S.A - PRUDENCIAL | D29: C0051987 | E29: C0081744 | F29: b1 | G29: 2 | H29: 8 | I29: SAO PAULO | J29: SP | K29: 06/2026 | L29: 99778656 | M29: 53810851 | N29: 24713706 | O29: 92122935 | P29: 82698919 | Q29: 7655721 | R29: 901621 | S29: 53 | T29: 0 | U29: =IFERROR(CHOOSE(G29,"Público","Privado Nacional","Privado Estrangeiro"),"n.d.") -> Privado Nacional | V29: =IF(AND(ISNUMBER(M29),ISNUMBER(L29)),IF(L29>0,M29/L29,"n.d."),"NI") -> 0.53930222 | W29: =IF(AND(ISNUMBER(R29),ISNUMBER(Q29)),IF(Q29>0,R29/Q29,"n.d."),"NI") -> 0.11777088 | X29: =IF(ISNUMBER(L29),IF(L29>100000000,"Grande","Média/Pequena"),"Sem dado") -> Média/Pequena | Y29: {=_xlfn.IFS(ISNUMBER(W29)=FALSE,"Sem dado",W29>0.075,"Excelente",W29>0.04,"Bom",W29>0,"Fraco",TRUE,"Prejuízo")} -> Excelente
A30: SANTANDER SOCIEDADE DE CRÉDITO, FINANCIAMENTO E INVESTIMENTO S.A. | B30: 7707650 | C30: SANTANDER - PRUDENCIAL | D30: C0030379 | E30: C0080185 | F30: n1 | G30: 3 | H30: 14 | I30: SAO PAULO | J30: SP | K30: 06/2026 | L30: 94908733 | M30: 78916545 | N30: 8626164 | O30: 90101084 | P30: 84719722 | Q30: 4807649 | R30: 361088 | S30: 1 | T30: 0 | U30: =IFERROR(CHOOSE(G30,"Público","Privado Nacional","Privado Estrangeiro"),"n.d.") -> Privado Estrangeiro | V30: =IF(AND(ISNUMBER(M30),ISNUMBER(L30)),IF(L30>0,M30/L30,"n.d."),"NI") -> 0.8314993 | W30: =IF(AND(ISNUMBER(R30),ISNUMBER(Q30)),IF(Q30>0,R30/Q30,"n.d."),"NI") -> 0.075106981 | X30: =IF(ISNUMBER(L30),IF(L30>100000000,"Grande","Média/Pequena"),"Sem dado") -> Média/Pequena | Y30: {=_xlfn.IFS(ISNUMBER(W30)=FALSE,"Sem dado",W30>0.075,"Excelente",W30>0.04,"Bom",W30>0,"Fraco",TRUE,"Prejuízo")} -> Excelente
A31: STONE INSTITUIÇÃO DE PAGAMENTO S.A. | B31: 16501555 | C31: STONE IP - PRUDENCIAL | E31: C0084686 | F31: n4 | G31: 3 | H31: 41 | I31: SAO PAULO | J31: SP | K31: 06/2026 | L31: 89229885 | M31: 0 | N31: 33856104 | O31: 86020632 | P31: 35329072 | Q31: 3209254 | R31: 867035 | S31: 1 | T31: 0 | U31: =IFERROR(CHOOSE(G31,"Público","Privado Nacional","Privado Estrangeiro"),"n.d.") -> Privado Estrangeiro | V31: =IF(AND(ISNUMBER(M31),ISNUMBER(L31)),IF(L31>0,M31/L31,"n.d."),"NI") -> 0 | W31: =IF(AND(ISNUMBER(R31),ISNUMBER(Q31)),IF(Q31>0,R31/Q31,"n.d."),"NI") -> 0.27016715 | X31: =IF(ISNUMBER(L31),IF(L31>100000000,"Grande","Média/Pequena"),"Sem dado") -> Média/Pequena | Y31: {=_xlfn.IFS(ISNUMBER(W31)=FALSE,"Sem dado",W31>0.075,"Excelente",W31>0.04,"Bom",W31>0,"Fraco",TRUE,"Prejuízo")} -> Excelente
A32: BANCO DO NORDESTE DO BRASIL S.A. | B32: 7237373 | C32: BCO DO NORDESTE DO BRASIL S.A. - PRUDENCIAL | E32: C0081593 | F32: b1 | G32: 1 | H32: 8 | I32: FORTALEZA | J32: CE | K32: 06/2026 | L32: 81039783 | M32: 17779920 | N32: 44768452 | O32: 64226772 | P32: 23269171 | Q32: 16813010 | R32: 1057412 | S32: 301 | T32: 1 | U32: =IFERROR(CHOOSE(G32,"Público","Privado Nacional","Privado Estrangeiro"),"n.d.") -> Público | V32: =IF(AND(ISNUMBER(M32),ISNUMBER(L32)),IF(L32>0,M32/L32,"n.d."),"NI") -> 0.21939743 | W32: =IF(AND(ISNUMBER(R32),ISNUMBER(Q32)),IF(Q32>0,R32/Q32,"n.d."),"NI") -> 0.062892486 | X32: =IF(ISNUMBER(L32),IF(L32>100000000,"Grande","Média/Pequena"),"Sem dado") -> Média/Pequena | Y32: {=_xlfn.IFS(ISNUMBER(W32)=FALSE,"Sem dado",W32>0.075,"Excelente",W32>0.04,"Bom",W32>0,"Fraco",TRUE,"Prejuízo")} -> Bom
A33: BANCO PAN S.A. | B33: 59285411 | C33: BTG PACTUAL - PRUDENCIAL | D33: C0049944 | E33: C0080336 | F33: b1 | G33: 2 | H33: 8 | I33: RIO DE JANEIRO | J33: RJ | K33: 06/2026 | L33: 77255474 | M33: 35566859 | N33: 24319234 | O33: 68495128 | P33: 64315922 | Q33: 8760346 | R33: 689725 | S33: 2 | T33: 0 | U33: =IFERROR(CHOOSE(G33,"Público","Privado Nacional","Privado Estrangeiro"),"n.d.") -> Privado Nacional | V33: =IF(AND(ISNUMBER(M33),ISNUMBER(L33)),IF(L33>0,M33/L33,"n.d."),"NI") -> 0.46037979 | W33: =IF(AND(ISNUMBER(R33),ISNUMBER(Q33)),IF(Q33>0,R33/Q33,"n.d."),"NI") -> 0.078732621 | X33: =IF(ISNUMBER(L33),IF(L33>100000000,"Grande","Média/Pequena"),"Sem dado") -> Média/Pequena | Y33: {=_xlfn.IFS(ISNUMBER(W33)=FALSE,"Sem dado",W33>0.075,"Excelente",W33>0.04,"Bom",W33>0,"Fraco",TRUE,"Prejuízo")} -> Excelente
A34: GETNET ADQUIRÊNCIA E SERVIÇOS PARA MEIOS DE PAGAMENTO S.A. INSTITUIÇÃO DE PAGAMENTO | B34: 10440482 | C34: SANTANDER - PRUDENCIAL | E34: C0080185 | F34: n4 | G34: 3 | H34: 41 | I34: SAO PAULO | J34: SP | K34: 06/2026 | L34: 74198667 | M34: 0 | N34: 471650 | O34: 70373351 | P34: 457227 | Q34: 3825316 | R34: 529101 | S34: 1 | T34: 0 | U34: =IFERROR(CHOOSE(G34,"Público","Privado Nacional","Privado Estrangeiro"),"n.d.") -> Privado Estrangeiro | V34: =IF(AND(ISNUMBER(M34),ISNUMBER(L34)),IF(L34>0,M34/L34,"n.d."),"NI") -> 0 | W34: =IF(AND(ISNUMBER(R34),ISNUMBER(Q34)),IF(Q34>0,R34/Q34,"n.d."),"NI") -> 0.13831563 | X34: =IF(ISNUMBER(L34),IF(L34>100000000,"Grande","Média/Pequena"),"Sem dado") -> Média/Pequena | Y34: {=_xlfn.IFS(ISNUMBER(W34)=FALSE,"Sem dado",W34>0.075,"Excelente",W34>0.04,"Bom",W34>0,"Fraco",TRUE,"Prejuízo")} -> Excelente
A35: PAGSEGURO INTERNET INSTITUIÇÃO DE PAGAMENTO S.A. | B35: 8561701 | C35: PAGSEGURO - PRUDENCIAL | E35: C0084813 | F35: n4 | G35: 2 | H35: 41 | I35: SAO PAULO | J35: SP | K35: 06/2026 | L35: 73530147 | M35: 746551 | N35: 5259611 | O35: 67499312 | P35: 46766864 | Q35: 6030835 | R35: 463519 | S35: 1 | T35: 0 | U35: =IFERROR(CHOOSE(G35,"Público","Privado Nacional","Privado Estrangeiro"),"n.d.") -> Privado Nacional | V35: =IF(AND(ISNUMBER(M35),ISNUMBER(L35)),IF(L35>0,M35/L35,"n.d."),"NI") -> 0.010152992 | W35: =IF(AND(ISNUMBER(R35),ISNUMBER(Q35)),IF(Q35>0,R35/Q35,"n.d."),"NI") -> 0.07685818 | X35: =IF(ISNUMBER(L35),IF(L35>100000000,"Grande","Média/Pequena"),"Sem dado") -> Média/Pequena | Y35: {=_xlfn.IFS(ISNUMBER(W35)=FALSE,"Sem dado",W35>0.075,"Excelente",W35>0.04,"Bom",W35>0,"Fraco",TRUE,"Prejuízo")} -> Excelente
A36: BANCO BRADESCO FINANCIAMENTOS S.A. | B36: 7207996 | C36: BRADESCO - PRUDENCIAL | D36: C0010045 | E36: C0080075 | F36: b1 | G36: 2 | H36: 8 | I36: OSASCO | J36: SP | K36: 06/2026 | L36: 68748096 | M36: 52483412 | N36: 60748 | O36: 68114489 | P36: 65248099 | Q36: 633608 | R36: 12331 | S36: 2 | T36: 5 | U36: =IFERROR(CHOOSE(G36,"Público","Privado Nacional","Privado Estrangeiro"),"n.d.") -> Privado Nacional | V36: =IF(AND(ISNUMBER(M36),ISNUMBER(L36)),IF(L36>0,M36/L36,"n.d."),"NI") -> 0.76341623 | W36: =IF(AND(ISNUMBER(R36),ISNUMBER(Q36)),IF(Q36>0,R36/Q36,"n.d."),"NI") -> 0.01946156 | X36: =IF(ISNUMBER(L36),IF(L36>100000000,"Grande","Média/Pequena"),"Sem dado") -> Média/Pequena | Y36: {=_xlfn.IFS(ISNUMBER(W36)=FALSE,"Sem dado",W36>0.075,"Excelente",W36>0.04,"Bom",W36>0,"Fraco",TRUE,"Prejuízo")} -> Fraco
A37: BANCO DA AMAZONIA S.A. | B37: 4902979 | C37: BCO DA AMAZONIA S.A. - PRUDENCIAL | E37: C0081249 | F37: b1 | G37: 1 | H37: 2 | I37: BELEM | J37: PA | K37: 06/2026 | L37: 67352881 | M37: 38713829 | N37: 21699434 | O37: 60078810 | P37: 15601132 | Q37: 7274071 | R37: 353060 | S37: 115 | T37: 0 | U37: =IFERROR(CHOOSE(G37,"Público","Privado Nacional","Privado Estrangeiro"),"n.d.") -> Público | V37: =IF(AND(ISNUMBER(M37),ISNUMBER(L37)),IF(L37>0,M37/L37,"n.d."),"NI") -> 0.57479099 | W37: =IF(AND(ISNUMBER(R37),ISNUMBER(Q37)),IF(Q37>0,R37/Q37,"n.d."),"NI") -> 0.048536782 | X37: =IF(ISNUMBER(L37),IF(L37>100000000,"Grande","Média/Pequena"),"Sem dado") -> Média/Pequena | Y37: {=_xlfn.IFS(ISNUMBER(W37)=FALSE,"Sem dado",W37>0.075,"Excelente",W37>0.04,"Bom",W37>0,"Fraco",TRUE,"Prejuízo")} -> Bom
A38: BANCO ABC BRASIL S.A. | B38: 28195667 | C38: ABC-BRASIL - PRUDENCIAL | D38: C0041856 | E38: C0080312 | F38: b1 | G38: 3 | H38: 8 | I38: SAO PAULO | J38: SP | K38: 06/2026 | L38: 66147427 | M38: 18520743 | N38: 29173812 | O38: 58888511 | P38: 50226679 | Q38: 7258915 | R38: 487535 | S38: 13 | T38: 0 | U38: =IFERROR(CHOOSE(G38,"Público","Privado Nacional","Privado Estrangeiro"),"n.d.") -> Privado Estrangeiro | V38: =IF(AND(ISNUMBER(M38),ISNUMBER(L38)),IF(L38>0,M38/L38,"n.d."),"NI") -> 0.27999189 | W38: =IF(AND(ISNUMBER(R38),ISNUMBER(Q38)),IF(Q38>0,R38/Q38,"n.d."),"NI") -> 0.067163619 | X38: =IF(ISNUMBER(L38),IF(L38>100000000,"Grande","Média/Pequena"),"Sem dado") -> Média/Pequena | Y38: {=_xlfn.IFS(ISNUMBER(W38)=FALSE,"Sem dado",W38>0.075,"Excelente",W38>0.04,"Bom",W38>0,"Fraco",TRUE,"Prejuízo")} -> Bom
A39: BANCO VOLKSWAGEN S.A. | B39: 59109165 | C39: VOLKSWAGEN - PRUDENCIAL | E39: C0080202 | F39: b2 | G39: 3 | H39: 8 | I39: SAO PAULO | J39: SP | K39: 06/2026 | L39: 61250495 | M39: 50345582 | N39: 819927 | O39: 55986251 | P39: 47916041 | Q39: 5264244 | R39: -203091 | S39: 2 | T39: 0 | U39: =IFERROR(CHOOSE(G39,"Público","Privado Nacional","Privado Estrangeiro"),"n.d.") -> Privado Estrangeiro | V39: =IF(AND(ISNUMBER(M39),ISNUMBER(L39)),IF(L39>0,M39/L39,"n.d."),"NI") -> 0.82196204 | W39: =IF(AND(ISNUMBER(R39),ISNUMBER(Q39)),IF(Q39>0,R39/Q39,"n.d."),"NI") -> -0.038579329 | X39: =IF(ISNUMBER(L39),IF(L39>100000000,"Grande","Média/Pequena"),"Sem dado") -> Média/Pequena | Y39: {=_xlfn.IFS(ISNUMBER(W39)=FALSE,"Sem dado",W39>0.075,"Excelente",W39>0.04,"Bom",W39>0,"Fraco",TRUE,"Prejuízo")} -> Prejuízo
A40: BANCO BNP PARIBAS BRASIL S.A. | B40: 1522368 | C40: BNP PARIBAS - PRUDENCIAL | E40: C0080673 | F40: b1 | G40: 3 | H40: 8 | I40: SAO PAULO | J40: SP | K40: 06/2026 | L40: 58787929 | M40: 6716037 | N40: 21646070 | O40: 54077310 | P40: 34516225 | Q40: 4710619 | R40: 86546 | S40: 2 | T40: 0 | U40: =IFERROR(CHOOSE(G40,"Público","Privado Nacional","Privado Estrangeiro"),"n.d.") -> Privado Estrangeiro | V40: =IF(AND(ISNUMBER(M40),ISNUMBER(L40)),IF(L40>0,M40/L40,"n.d."),"NI") -> 0.11424177 | W40: =IF(AND(ISNUMBER(R40),ISNUMBER(Q40)),IF(Q40>0,R40/Q40,"n.d."),"NI") -> 0.018372532 | X40: =IF(ISNUMBER(L40),IF(L40>100000000,"Grande","Média/Pequena"),"Sem dado") -> Média/Pequena | Y40: {=_xlfn.IFS(ISNUMBER(W40)=FALSE,"Sem dado",W40>0.075,"Excelente",W40>0.04,"Bom",W40>0,"Fraco",TRUE,"Prejuízo")} -> Fraco
A41: BANCO C6 CONSIGNADO S.A. | B41: 61348538 | C41: BANCO C6 - PRUDENCIAL | D41: C0052072 | E41: C0084844 | F41: b1 | G41: 2 | H41: 8 | I41: SAO PAULO | J41: SP | K41: 06/2026 | L41: 56164263 | M41: 42537256 | N41: 7432727 | O41: 52511688 | P41: 39443515 | Q41: 3652575 | R41: 559375 | S41: 2 | T41: 0 | U41: =IFERROR(CHOOSE(G41,"Público","Privado Nacional","Privado Estrangeiro"),"n.d.") -> Privado Nacional | V41: =IF(AND(ISNUMBER(M41),ISNUMBER(L41)),IF(L41>0,M41/L41,"n.d."),"NI") -> 0.75737228 | W41: =IF(AND(ISNUMBER(R41),ISNUMBER(Q41)),IF(Q41>0,R41/Q41,"n.d."),"NI") -> 0.15314538 | X41: =IF(ISNUMBER(L41),IF(L41>100000000,"Grande","Média/Pequena"),"Sem dado") -> Média/Pequena | Y41: {=_xlfn.IFS(ISNUMBER(W41)=FALSE,"Sem dado",W41>0.075,"Excelente",W41>0.04,"Bom",W41>0,"Fraco",TRUE,"Prejuízo")} -> Excelente
...

Sheet Totais_Fonte
A1: TOTAIS DA FONTE | IFData Junho 2026
A2: Fonte: IF.data, Banco Central do Brasil | Linhas de totais do arquivo IFData_Junho_2026.csv, por TCB, TC e TI | Valores monetários em R$ mil
A4: TCB | Tipo de Consolidado Bancário
A5: Código | B5: Descrição | C5: Linha | D5: Ativo Total (R$ mil) | E5: Carteira de Crédito (R$ mil) | F5: Títulos e Valores Mobiliários (R$ mil) | G5: Passivo Exigível (R$ mil) | H5: Captações (R$ mil) | I5: Patrimônio Líquido (R$ mil) | J5: Lucro Líquido (R$ mil) | K5: Número de Agências | L5: Postos de Atendimento
A6: b1 | B6: Banco Comercial, Banco Múltiplo com Carteira Comercial ou Caixa Econômica | C6: Total | D6: 14285826209 | E6: 5511754811 | F6: 3518123267 | G6: 13157506808 | H6: 11469908861 | I6: 1128319401 | J6: 80608469 | K6: 13386 | L6: 8067
A7: b1 | B7: Banco Comercial, Banco Múltiplo com Carteira Comercial ou Caixa Econômica | C7: % do sistema | D7: 0.7327 | E7: 0.7462 | F7: 0.795 | G7: 0.7537 | H7: 0.8111 | I7: 0.5529 | J7: 0.5252 | K7: 0.8971 | L7: 0.4476
A8: b2 | B8: Banco Múltiplo sem Carteira Comercial ou Banco de Investimento ou Banco de Câmbio | C8: Total | D8: 931799121 | E8: 430091463 | F8: 108094396 | G8: 650002745 | H8: 408314941 | I8: 281796376 | J8: 27442035 | K8: 108 | L8: 7
A9: b2 | B9: Banco Múltiplo sem Carteira Comercial ou Banco de Investimento ou Banco de Câmbio | C9: % do sistema | D9: 0.0478 | E9: 0.0582 | F9: 0.0244 | G9: 0.0372 | H9: 0.0289 | I9: 0.1381 | J9: 0.1788 | K9: 0.0072 | L9: 0.0004
A10: b3S | B10: Cooperativa de Crédito Singulares | C10: Total | D10: 992158871 | E10: 534336219 | F10: 185424312 | G10: 852161871 | H10: 676043108 | I10: 139996999 | J10: 8584458 | K10: 0 | L10: 9928
A11: b3S | B11: Cooperativa de Crédito Singulares | C11: % do sistema | D11: 0.0509 | E11: 0.0723 | F11: 0.0419 | G11: 0.0488 | H11: 0.0478 | I11: 0.0686 | J11: 0.0559 | K11: 0 | L11: 0.5509
A12: b3C | B12: Central e Confederação de Cooperativas de Crédito | C12: Total | D12: 254740242 | E12: 2759784 | F12: 98467430 | G12: 235183278 | H12: 26776352 | I12: 19556964 | J12: 677772 | K12: 0 | L12: 11
A13: b3C | B13: Central e Confederação de Cooperativas de Crédito | C13: % do sistema | D13: 0.0131 | E13: 0.0004 | F13: 0.0223 | G13: 0.0135 | H13: 0.0019 | I13: 0.0096 | J13: 0.0044 | K13: 0 | L13: 0.0006
A14: b4 | B14: Banco de Desenvolvimento | C14: Total | D14: 1121980384 | E14: 410286392 | F14: 219674537 | G14: 932408406 | H14: 697618375 | I14: 189571978 | J14: 11549205 | K14: 13 | L14: 0
A15: b4 | B15: Banco de Desenvolvimento | C15: % do sistema | D15: 0.0575 | E15: 0.0555 | F15: 0.0496 | G15: 0.0534 | H15: 0.0493 | I15: 0.0929 | J15: 0.0753 | K15: 0.0009 | L15: 0
A16: n1 | B16: Não Bancário de Crédito | C16: Total | D16: 734344385 | E16: 384887710 | F16: 143337276 | G16: 624999723 | H16: 522307010 | I16: 109344662 | J16: 9405391 | K16: 656 | L16: 0
A17: n1 | B17: Não Bancário de Crédito | C17: % do sistema | D17: 0.0377 | E17: 0.0521 | F17: 0.0324 | G17: 0.0358 | H17: 0.0369 | I17: 0.0536 | J17: 0.0613 | K17: 0.044 | L17: 0
... A21: n4 | B21: Instituições de Pagamento | C21: % do sistema | D21: 0.047 | E21: 0.0151 | F21: 0.0205 | G21: 0.0454 | H21: 0.0149 | I21: 0.0604 | J21: 0.0677 | K21: 0.0131 | L21: 0
A23: TC | Tipo de Controle
A24: Código | B24: Descrição | C24: Linha | D24: Ativo Total (R$ mil) | E24: Carteira de Crédito (R$ mil) | F24: Títulos e Valores Mobiliários (R$ mil) | G24: Passivo Exigível (R$ mil) | H24: Captações (R$ mil) | I24: Patrimônio Líquido (R$ mil) | J24: Lucro Líquido (R$ mil) | K24: Número de Agências | L24: Postos de Atendimento
A25: 1 | B25: Público | C25: Total | D25: 6391175338 | E25: 2999719019 | F25: 1569544736 | G25: 5837080041 | H25: 5003609740 | I25: 554095297 | J25: 29620371 | K25: 8291 | L25: 1527
A26: 1 | B26: Público | C26: % do sistema | D26: 0.3278 | E26: 0.4061 | F26: 0.3547 | G26: 0.3344 | H26: 0.3538 | I26: 0.2715 | J26: 0.193 | K26: 0.5556 | L26: 0.0847
A27: 2 | B27: Privado Nacional | C27: Total | D27: 9761967937 | E27: 3260463203 | F27: 2123358155 | G27: 8626395920 | H27: 6808625220 | I27: 1135572016 | J27: 96755434 | K27: 4917 | L27: 13628
A28: 2 | B28: Privado Nacional | C28: % do sistema | D28: 0.5007 | E28: 0.4414 | F28: 0.4798 | G28: 0.4941 | H28: 0.4815 | I28: 0.5565 | J28: 0.6305 | K28: 0.3295 | L28: 0.7561
A29: 3 | B29: Privado com Controle Estrangeiro | C29: Total | D29: 3344608879 | E29: 1125986266 | F29: 732464125 | G29: 2993619249 | H29: 2328706032 | I29: 350989630 | J29: 27091362 | K29: 1714 | L29: 2868
A30: 3 | B30: Privado com Controle Estrangeiro | C30: % do sistema | D30: 0.1715 | E30: 0.1524 | F30: 0.1655 | G30: 0.1715 | H30: 0.1647 | I30: 0.172 | J30: 0.1765 | K30: 0.1149 | L30: 0.1591
A32: TI | Tipo de Instituição
A33: Código | B33: Descrição | C33: Linha | D33: Ativo Total (R$ mil) | E33: Carteira de Crédito (R$ mil) | F33: Títulos e Valores Mobiliários (R$ mil) | G33: Passivo Exigível (R$ mil) | H33: Captações (R$ mil) | I33: Patrimônio Líquido (R$ mil) | J33: Lucro Líquido (R$ mil) | K33: Número de Agências | L33: Postos de Atendimento
A34: 1 | B34: Banco do Brasil - Banco Múltiplo | C34: Total | D34: 2461086914 | E34: 1065710905 | F34: 714731784 | G34: 2279753810 | H34: 1974660924 | I34: 181333105 | J34: 6216056 | K34: 3932 | L34: 309
A35: 1 | B35: Banco do Brasil - Banco Múltiplo | C35: % do sistema | D35: 0.1262 | E35: 0.1443 | F35: 0.1615 | G35: 0.1306 | H35: 0.1396 | I35: 0.0889 | J35: 0.0405 | K35: 0.2635 | L35: 0.0171
A36: 2 | B36: Banco Comercial | C36: Total | D36: 135301188 | E36: 77746731 | F36: 34673576 | G36: 121581570 | H36: 58147454 | I36: 13719618 | J36: 734878 | K36: 158 | L36: 1535
A37: 2 | B37: Banco Comercial | C37: % do sistema | D37: 0.0069 | E37: 0.0105 | F37: 0.0078 | G37: 0.007 | H37: 0.0041 | I37: 0.0067 | J37: 0.0048 | K37: 0.0106 | L37: 0.0852
A38: 3 | B38: Banco Comercial Cooperativo | C38: Total | D38: 0 | E38: 0 | F38: 0 | G38: 0 | H38: 0 | I38: 0 | J38: 0 | K38: 0 | L38: 0
A39: 3 | B39: Banco Comercial Cooperativo | C39: % do sistema | D39: 0 | E39: 0 | F39: 0 | G39: 0 | H39: 0 | I39: 0 | J39: 0 | K39: 0 | L39: 0
A40: 4 | B40: BNDES | C40: Total | D40: 1073403746 | E40: 375703869 | F40: 209161034 | G40: 892700475 | H40: 661452493 | I40: 180703272 | J40: 11153448 | K40: 5 | L40: 0
A41: 4 | B41: BNDES | C41: % do sistema | D41: 0.0551 | E41: 0.0509 | F41: 0.0473 | G41: 0.0511 | H41: 0.0468 | I41: 0.0886 | J41: 0.0727 | K41: 0.0003 | L41: 0
A42: 5 | B42: Banco de Desenvolvimento | C42: Total | D42: 48576638 | E42: 34582523 | F42: 10513503 | G42: 39707932 | H42: 36165882 | I42: 8868706 | J42: 395757 | K42: 8 | L42: 0
A43: 5 | B43: Banco de Desenvolvimento | C43: % do sistema | D43: 0.0025 | E43: 0.0047 | F43: 0.0024 | G43: 0.0023 | H43: 0.0026 | I43: 0.0043 | J43: 0.0026 | K43: 0.0005 | L43: 0
A44: 6 | B44: Caixa Econômica Federal | C44: Total | D44: 2368147225 | E44: 1362330927 | F44: 452416774 | G44: 2249779433 | H44: 2063880327 | I44: 118367792 | J44: 6585794 | K44: 3000 | L44: 868
A45: 6 | B45: Caixa Econômica Federal | C45: % do sistema | D45: 0.1215 | E45: 0.1844 | F45: 0.1022 | G45: 0.1289 | H45: 0.146 | I45: 0.058 | J45: 0.0429 | K45: 0.201 | L45: 0.0482
... A85: 44 | B85: Sociedades de Empréstimo entre Pessoas | C85: % do sistema | D85: 0 | E85: 0 | F85: 0 | G85: 0 | H85: 0 | I85: 0 | J85: 0 | K85: 0.0016 | L85: 0

Sheet Dicionário
A1: DICIONÁRIO DE DADOS | IFData Junho 2026
A2: Significado de cada coluna da aba Base_IFData e dos códigos de classificação (TCB, TC e TI). Valores monetários em R$ mil.
A4: COLUNAS DA BASE
A5: Col. | B5: Coluna | C5: Nome completo | D5: Tipo | E5: O que significa na prática
A6: A | B6: Instituição | C6: Nome da instituição financeira | D6: Texto | E6: Razão social registrada no Banco Central. Cada linha é uma instituição individual: holdings e controladas aparecem em linhas separadas.
A7: B | B7: Código | C7: Código de identificação da instituição | D7: Número | E7: Raiz do CNPJ da instituição, sem zeros à esquerda (o Banco do Brasil aparece como 0). Único por linha.
A8: C | B8: Conglomerado Prudencial (Nome) | C8: Nome do conglomerado prudencial | D8: Texto | E8: Grupo prudencial ao qual a instituição pertence. Vazio quando a instituição não integra conglomerado prudencial. Use para agregar instituições do mesmo grupo.
A9: D | B9: Conglomerado Financeiro (Cód.) | C9: Código do conglomerado financeiro | D9: Código | E9: Identificador do conglomerado financeiro (formato C0000000). Vazio quando a instituição não integra conglomerado financeiro.
A10: E | B10: Conglomerado Prudencial (Cód.) | C10: Código do conglomerado prudencial | D10: Código | E10: Identificador do conglomerado prudencial (formato C0000000), correspondente ao nome da coluna C.
A11: F | B11: TCB | C11: Tipo de Consolidado Bancário | D11: Código | E11: Classifica o tipo de instituição. Ver tabela de códigos TCB abaixo.
A12: G | B12: TC | C12: Tipo de Controle | D12: Código | E12: 1 = Público; 2 = Privado Nacional; 3 = Privado com Controle Estrangeiro. Ver tabela abaixo.
A13: H | B13: TI | C13: Tipo de Instituição | D13: Código | E13: Classificação detalhada do tipo de instituição. Ver tabela de códigos TI abaixo.
A14: I | B14: Cidade | C14: Município da sede | D14: Texto | E14: Cidade onde a instituição tem sua sede registrada no Banco Central.
A15: J | B15: UF | C15: Unidade da Federação da sede | D15: Texto | E15: Estado da sede da instituição.
A16: K | B16: Data | C16: Data-base dos dados | D16: Texto | E16: Mês e ano de referência. 06/2026 = posição de junho de 2026.
... A28: W | B28: ROE do semestre | C28: Retorno sobre o Patrimônio Líquido no semestre | D28: Fórmula | E28: Calculado: Lucro Líquido ÷ Patrimônio Líquido. Mede o lucro gerado por real de capital próprio no semestre (não anualizado). Retorna NI quando não informado e n.d. quando o Patrimônio Líquido é zero ou negativo.
A30: NOTAS DE LEITURA
A31: 1 | B31: Unidade: valores monetários em R$ mil. R$ 1 bilhão equivale a 1.000.000 nesta unidade.
A32: 2 | B32: ="NI = não informado na fonte. " & COUNTIF(Base_IFData_Original!$L$5:$L$1626,"NI") & " instituições têm NI nas colunas de valores monetários: entram nas contagens, mas ficam fora de somas, médias e medianas." -> NI = não informado na fonte. 51 instituições têm NI nas colunas de valores monetários: entram nas contagens, mas ficam fora de somas, médias e medianas.
A33: 3 | B33: Instituições individuais: quando uma holding e suas controladas estão na base, seus ativos aparecem em linhas separadas e a soma geral pode conter sobreposição. Para análise por grupo, agregue pelo Conglomerado Prudencial.
A34: 4 | B34: Ordenação: a base está ordenada por Ativo Total decrescente, com as instituições de valores NI ao final.
A35: 5 | B35: Totais da fonte: as linhas de totais do arquivo original (por TCB, TC e TI) ficam na aba Totais_Fonte, conferidas contra as somas da base.
A37: CÓDIGOS TCB | Tipo de Consolidado Bancário (coluna F)
B38: Código | C38: Descrição | D38: Instituições (nº) | E38: Maior instituição por Ativo Total
B39: b1 | C39: Banco Comercial, Banco Múltiplo com Carteira Comercial ou Caixa Econômica | D39: =COUNTIFS(Base_IFData_Original!$F$5:$F$1626,B39) -> 116 | E39: =IF(D39=0,"sem instituições na base",INDEX(Base_IFData_Original!$A$5:$A$1626,MATCH(1,INDEX((Base_IFData_Original!$F$5:$F$1626=B39)*(Base_IFData_Original!$L$5:$L$1626=_xlfn.MAXIFS(Base_IFData_Original!$L$5:$L$1626,Base_IFData_Original!$F$5:$F$1626,B39)),0),0))) -> BANCO DO BRASIL S.A.
B40: b2 | C40: Banco Múltiplo sem Carteira Comercial ou Banco de Investimento ou Banco de Câmbio | D40: =COUNTIFS(Base_IFData_Original!$F$5:$F$1626,B40) -> 50 | E40: =IF(D40=0,"sem instituições na base",INDEX(Base_IFData_Original!$A$5:$A$1626,MATCH(1,INDEX((Base_IFData_Original!$F$5:$F$1626=B40)*(Base_IFData_Original!$L$5:$L$1626=_xlfn.MAXIFS(Base_IFData_Original!$L$5:$L$1626,Base_IFData_Original!$F$5:$F$1626,B40)),0),0))) -> ITAÚ UNIBANCO HOLDING S.A.
B41: b3S | C41: Cooperativa de Crédito Singular | D41: =COUNTIFS(Base_IFData_Original!$F$5:$F$1626,B41) -> 729 | E41: =IF(D41=0,"sem instituições na base",INDEX(Base_IFData_Original!$A$5:$A$1626,MATCH(1,INDEX((Base_IFData_Original!$F$5:$F$1626=B41)*(Base_IFData_Original!$L$5:$L$1626=_xlfn.MAXIFS(Base_IFData_Original!$L$5:$L$1626,Base_IFData_Original!$F$5:$F$1626,B41)),0),0))) -> COOPERATIVA DE CREDITO CREDICITRUS
B42: b3C | C42: Central e Confederação de Cooperativas de Crédito | D42: =COUNTIFS(Base_IFData_Original!$F$5:$F$1626,B42) -> 27 | E42: =IF(D42=0,"sem instituições na base",INDEX(Base_IFData_Original!$A$5:$A$1626,MATCH(1,INDEX((Base_IFData_Original!$F$5:$F$1626=B42)*(Base_IFData_Original!$L$5:$L$1626=_xlfn.MAXIFS(Base_IFData_Original!$L$5:$L$1626,Base_IFData_Original!$F$5:$F$1626,B42)),0),0))) -> COOPERATIVA CENTRAL DE CRÉDITO DE MINAS GERAIS LTDA. - SICOOB CENTRAL CREDIMINAS
B43: b4 | C43: Banco de Desenvolvimento | D43: =COUNTIFS(Base_IFData_Original!$F$5:$F$1626,B43) -> 4 | E43: =IF(D43=0,"sem instituições na base",INDEX(Base_IFData_Original!$A$5:$A$1626,MATCH(1,INDEX((Base_IFData_Original!$F$5:$F$1626=B43)*(Base_IFData_Original!$L$5:$L$1626=_xlfn.MAXIFS(Base_IFData_Original!$L$5:$L$1626,Base_IFData_Original!$F$5:$F$1626,B43)),0),0))) -> BANCO NACIONAL DE DESENVOLVIMENTO ECONOMICO E SOCIAL
B44: n1 | C44: Não Bancário de Crédito | D44: =COUNTIFS(Base_IFData_Original!$F$5:$F$1626,B44) -> 290 | E44: =IF(D44=0,"sem instituições na base",INDEX(Base_IFData_Original!$A$5:$A$1626,MATCH(1,INDEX((Base_IFData_Original!$F$5:$F$1626=B44)*(Base_IFData_Original!$L$5:$L$1626=_xlfn.MAXIFS(Base_IFData_Original!$L$5:$L$1626,Base_IFData_Original!$F$5:$F$1626,B44)),0),0))) -> NU FINANCEIRA S.A. - SOCIEDADE DE CRÉDITO, FINANCIAMENTO E INVESTIMENTO
B45: n2 | C45: Não Bancário de Mercado de Capitais | D45: =COUNTIFS(Base_IFData_Original!$F$5:$F$1626,B45) -> 210 | E45: =IF(D45=0,"sem instituições na base",INDEX(Base_IFData_Original!$A$5:$A$1626,MATCH(1,INDEX((Base_IFData_Original!$F$5:$F$1626=B45)*(Base_IFData_Original!$L$5:$L$1626=_xlfn.MAXIFS(Base_IFData_Original!$L$5:$L$1626,Base_IFData_Original!$F$5:$F$1626,B45)),0),0))) -> XP INVESTIMENTOS CORRETORA DE CÂMBIO,TÍTULOS E VALORES MOBILIÁRIOS S/A
B46: n4 | C46: Instituições de Pagamento | D46: =COUNTIFS(Base_IFData_Original!$F$5:$F$1626,B46) -> 196 | E46: =IF(D46=0,"sem instituições na base",INDEX(Base_IFData_Original!$A$5:$A$1626,MATCH(1,INDEX((Base_IFData_Original!$F$5:$F$1626=B46)*(Base_IFData_Original!$L$5:$L$1626=_xlfn.MAXIFS(Base_IFData_Original!$L$5:$L$1626,Base_IFData_Original!$F$5:$F$1626,B46)),0),0))) -> REDECARD INSTITUIÇÃO DE PAGAMENTO S.A.
A48: CÓDIGOS TC | Tipo de Controle (coluna G)
B49: Código | C49: Descrição | D49: Instituições (nº) | E49: Maior instituição por Ativo Total
B50: 1 | C50: Público | D50: =COUNTIFS(Base_IFData_Original!$G$5:$G$1626,B50) -> 39 | E50: =IF(D50=0,"sem instituições na base",INDEX(Base_IFData_Original!$A$5:$A$1626,MATCH(1,INDEX((Base_IFData_Original!$G$5:$G$1626=B50)*(Base_IFData_Original!$L$5:$L$1626=_xlfn.MAXIFS(Base_IFData_Original!$L$5:$L$1626,Base_IFData_Original!$G$5:$G$1626,B50)),0),0))) -> BANCO DO BRASIL S.A.
B51: 2 | C51: Privado Nacional | D51: =COUNTIFS(Base_IFData_Original!$G$5:$G$1626,B51) -> 1353 | E51: =IF(D51=0,"sem instituições na base",INDEX(Base_IFData_Original!$A$5:$A$1626,MATCH(1,INDEX((Base_IFData_Original!$G$5:$G$1626=B51)*(Base_IFData_Original!$L$5:$L$1626=_xlfn.MAXIFS(Base_IFData_Original!$L$5:$L$1626,Base_IFData_Original!$G$5:$G$1626,B51)),0),0))) -> ITAÚ UNIBANCO S.A.
B52: 3 | C52: Privado com Controle Estrangeiro | D52: =COUNTIFS(Base_IFData_Original!$G$5:$G$1626,B52) -> 230 | E52: =IF(D52=0,"sem instituições na base",INDEX(Base_IFData_Original!$A$5:$A$1626,MATCH(1,INDEX((Base_IFData_Original!$G$5:$G$1626=B52)*(Base_IFData_Original!$L$5:$L$1626=_xlfn.MAXIFS(Base_IFData_Original!$L$5:$L$1626,Base_IFData_Original!$G$5:$G$1626,B52)),0),0))) -> BANCO SANTANDER (BRASIL) S.A.
A54: CÓDIGOS TI | Tipo de Instituição (coluna H)
B55: Código | C55: Descrição | D55: Instituições (nº) | E55: Maior instituição por Ativo Total
B56: 1 | C56: Banco do Brasil - Banco Múltiplo | D56: =COUNTIFS(Base_IFData_Original!$H$5:$H$1626,B56) -> 1 | E56: =IF(D56=0,"sem instituições na base",INDEX(Base_IFData_Original!$A$5:$A$1626,MATCH(1,INDEX((Base_IFData_Original!$H$5:$H$1626=B56)*(Base_IFData_Original!$L$5:$L$1626=_xlfn.MAXIFS(Base_IFData_Original!$L$5:$L$1626,Base_IFData_Original!$H$5:$H$1626,B56)),0),0))) -> BANCO DO BRASIL S.A.
...

Sheet Análises 1
A1: ANÁLISES 1 | IFData Junho 2026
A3: MEDIDAS DE RESUMO
A4: Nº | B4: O que fazer | C4: Fórmula aplicada | D4: Resultado | E4: Para reflexão
A5: 1 | B5: Qual é o ATIVO TOTAL MÉDIO das instituições da base? → Coluna L da Base_IFData | C5: =MÉDIA(Base_IFData!L5:L1626) | D5: =AVERAGE(Base_IFData!L5:L1626) -> 12411045 | E5: Compare com a mediana (exercício 2). O que a diferença entre as duas diz sobre a distribuição?
